<?xml version="1.0" ?>
<!-- =================================================================================== -->
<!-- |    This document was autogenerated by xacro from /project/franka_panda_sim_ws/src/franka_description/robots/panda_arm_camera.urdf.xacro | -->
<!-- |    EDITING THIS FILE BY HAND IS NOT RECOMMENDED                                 | -->
<!-- =================================================================================== -->
<!-- Franka robot with a camera attached -->
<robot name="panda_hand_camera">
    <!-- end for simulation -->
    <link name="world" />
    <joint name="panda_joint_world" type="fixed">
        <parent link="world" />
        <child link="panda_link0" />
        <origin rpy="0 0 0" xyz="0 0 0" />
        <!-- for simulation -->
        <dynamics damping="1.0" />
        <!-- end for simulation -->
    </joint>
    <link name="panda_link0">
        <visual>
            <geometry>
                <mesh filename="package://franka_description/meshes/visual/link0.dae" />
            </geometry>
        </visual>
        <collision>
            <geometry>
                <mesh filename="package://franka_description/meshes/collision/link0.stl" />
            </geometry>
        </collision>
        <!-- for simulation -->
        <inertial>
            <origin rpy="0 0 0" xyz="0 0 0" />
            <mass value="3.06" />
            <inertia ixx="0.3" ixy="0.0" ixz="0.0" iyy="0.3" iyz="0.0" izz="0.3" />
        </inertial>
        <!-- end for simulation -->
    </link>
    <link name="panda_link1">
        <visual>
            <geometry>
                <mesh filename="package://franka_description/meshes/visual/link1.dae" />
            </geometry>
        </visual>
        <collision>
            <geometry>
                <mesh filename="package://franka_description/meshes/collision/link1.stl" />
            </geometry>
        </collision>
        <!-- for simulation -->
        <inertial>
            <origin rpy="0 0 0" xyz="0 0 0" />
            <mass value="2.34" />
            <inertia ixx="0.3" ixy="0.0" ixz="0.0" iyy="0.3" iyz="0.0" izz="0.3" />
        </inertial>
        <!-- end for simulation -->
    </link>
    <joint name="panda_joint1" type="revolute">
        <safety_controller k_position="100.0" k_velocity="40.0" soft_lower_limit="-2.8973" soft_upper_limit="2.8973" />
        <origin rpy="0 0 0" xyz="0 0 0.333" />
        <parent link="panda_link0" />
        <child link="panda_link1" />
        <axis xyz="0 0 1" />
        <limit effort="87" lower="-2.8973" upper="2.8973" velocity="2.1750" />
    </joint>
    <link name="panda_link2">
        <visual>
            <geometry>
                <mesh filename="package://franka_description/meshes/visual/link2.dae" />
            </geometry>
        </visual>
        <collision>
            <origin rpy="0 0 0" xyz="0 0 0" />
            <geometry>
                <cylinder length="0.12" radius="0.06" />
            </geometry>
        </collision>
        <collision>
            <origin rpy="0 0 0" xyz="0 0 -0.06" />
            <geometry>
                <sphere radius="0.06" />
            </geometry>
        </collision>
        <collision>
            <origin rpy="0 0 0" xyz="0 0 0.06" />
            <geometry>
                <sphere radius="0.06" />
            </geometry>
        </collision>
        <!-- for simulation -->
        <inertial>
            <origin rpy="0 0 0" xyz="0 0 0" />
            <mass value="2.36" />
            <inertia ixx="0.3" ixy="0.0" ixz="0.0" iyy="0.3" iyz="0.0" izz="0.3" />
        </inertial>
        <!-- end for simulation -->
    </link>
    <joint name="panda_joint2" type="revolute">
        <safety_controller k_position="100.0" k_velocity="40.0" soft_lower_limit="-1.7628" soft_upper_limit="1.7628" />
        <origin rpy="-1.5707963267948966 0 0" xyz="0 0 0" />
        <parent link="panda_link1" />
        <child link="panda_link2" />
        <axis xyz="0 0 1" />
        <limit effort="87" lower="-1.7628" upper="1.7628" velocity="2.1750" />
    </joint>
    <link name="panda_link3">
        <visual>
            <geometry>
                <mesh filename="package://franka_description/meshes/visual/link3.dae" />
            </geometry>
        </visual>
        <collision>
            <origin rpy="0 0 0" xyz="0 0 -0.145" />
            <geometry>
                <cylinder length="0.15" radius="0.06" />
            </geometry>
        </collision>
        <collision>
            <origin rpy="0 0 0" xyz="0 0 -0.22" />
            <geometry>
                <sphere radius="0.06" />
            </geometry>
        </collision>
        <collision>
            <origin rpy="0 0 0" xyz="0 0 -0.07" />
            <geometry>
                <sphere radius="0.06" />
            </geometry>
        </collision>
        <!-- for simulation -->
        <inertial>
            <origin rpy="0 0 0" xyz="0 0 0" />
            <mass value="2.38" />
            <inertia ixx="0.3" ixy="0.0" ixz="0.0" iyy="0.3" iyz="0.0" izz="0.3" />
        </inertial>
        <!-- end for simulation -->
    </link>
    <joint name="panda_joint3" type="revolute">
        <safety_controller k_position="100.0" k_velocity="40.0" soft_lower_limit="-2.8973" soft_upper_limit="2.8973" />
        <origin rpy="1.5707963267948966 0 0" xyz="0 -0.316 0" />
        <parent link="panda_link2" />
        <child link="panda_link3" />
        <axis xyz="0 0 1" />
        <limit effort="87" lower="-2.8973" upper="2.8973" velocity="2.1750" />
    </joint>
    <link name="panda_link4">
        <visual>
            <geometry>
                <mesh filename="package://franka_description/meshes/visual/link4.dae" />
            </geometry>
        </visual>
        <collision>
            <origin rpy="0 0 0" xyz="0 0 0" />
            <geometry>
                <cylinder length="0.12" radius="0.06" />
            </geometry>
        </collision>
        <collision>
            <origin rpy="0 0 0" xyz="0 0 0.06" />
            <geometry>
                <sphere radius="0.06" />
            </geometry>
        </collision>
        <collision>
            <origin rpy="0 0 0" xyz="0 0 -0.06" />
            <geometry>
                <sphere radius="0.06" />
            </geometry>
        </collision>
        <!-- for simulation -->
        <inertial>
            <origin rpy="0 0 0" xyz="0 0 0" />
            <mass value="2.43" />
            <inertia ixx="0.3" ixy="0.0" ixz="0.0" iyy="0.3" iyz="0.0" izz="0.3" />
        </inertial>
        <!-- end for simulation -->
    </link>
    <joint name="panda_joint4" type="revolute">
        <safety_controller k_position="100.0" k_velocity="40.0" soft_lower_limit="-3.0718" soft_upper_limit="-0.0698" />
        <origin rpy="1.5707963267948966 0 0" xyz="0.0825 0 0" />
        <parent link="panda_link3" />
        <child link="panda_link4" />
        <axis xyz="0 0 1" />
        <limit effort="87" lower="-3.0718" upper="-0.0698" velocity="2.1750" />
    </joint>
    <link name="panda_link5">
        <visual>
            <geometry>
                <mesh filename="package://franka_description/meshes/visual/link5.dae" />
            </geometry>
        </visual>
        <collision>
            <origin rpy="0 0 0" xyz="0 0 -0.26" />
            <geometry>
                <cylinder length="0.1" radius="0.06" />
            </geometry>
        </collision>
        <collision>
            <origin rpy="0 0 0" xyz="0 0 -0.31" />
            <geometry>
                <sphere radius="0.06" />
            </geometry>
        </collision>
        <collision>
            <origin rpy="0 0 0" xyz="0 0 -0.21" />
            <geometry>
                <sphere radius="0.06" />
            </geometry>
        </collision>
        <collision>
            <origin rpy="0 0 0" xyz="0 0.08 -0.13" />
            <geometry>
                <cylinder length="0.14" radius="0.025" />
            </geometry>
        </collision>
        <collision>
            <origin rpy="0 0 0" xyz="0 0.08 -0.06" />
            <geometry>
                <sphere radius="0.025" />
            </geometry>
        </collision>
        <collision>
            <origin rpy="0 0 0" xyz="0 0.08 -0.20" />
            <geometry>
                <sphere radius="0.025" />
            </geometry>
        </collision>
        <!-- for simulation -->
        <inertial>
            <origin rpy="0 0 0" xyz="0 0 0" />
            <mass value="3.5" />
            <inertia ixx="0.3" ixy="0.0" ixz="0.0" iyy="0.3" iyz="0.0" izz="0.3" />
        </inertial>
        <!-- end for simulation -->
    </link>
    <joint name="panda_joint5" type="revolute">
        <safety_controller k_position="100.0" k_velocity="40.0" soft_lower_limit="-2.8973" soft_upper_limit="2.8973" />
        <origin rpy="-1.5707963267948966 0 0" xyz="-0.0825 0.384 0" />
        <parent link="panda_link4" />
        <child link="panda_link5" />
        <axis xyz="0 0 1" />
        <limit effort="12" lower="-2.8973" upper="2.8973" velocity="2.6100" />
    </joint>
    <link name="panda_link6">
        <visual>
            <geometry>
                <mesh filename="package://franka_description/meshes/visual/link6.dae" />
            </geometry>
        </visual>
        <collision>
            <origin rpy="0 0 0" xyz="0 0 -0.03" />
            <geometry>
                <cylinder length="0.08" radius="0.05" />
            </geometry>
        </collision>
        <collision>
            <origin rpy="0 0 0" xyz="0 0 0.01" />
            <geometry>
                <sphere radius="0.05" />
            </geometry>
        </collision>
        <collision>
            <origin rpy="0 0 0" xyz="0 0 -0.07" />
            <geometry>
                <sphere radius="0.05" />
            </geometry>
        </collision>
        <!-- for simulation -->
        <inertial>
            <origin rpy="0 0 0" xyz="0 0 0" />
            <mass value="1.47" />
            <inertia ixx="0.3" ixy="0.0" ixz="0.0" iyy="0.3" iyz="0.0" izz="0.3" />
        </inertial>
        <!-- end for simulation -->
    </link>
    <joint name="panda_joint6" type="revolute">
        <safety_controller k_position="100.0" k_velocity="40.0" soft_lower_limit="-0.0175" soft_upper_limit="3.7525" />
        <origin rpy="1.5707963267948966 0 0" xyz="0 0 0" />
        <parent link="panda_link5" />
        <child link="panda_link6" />
        <axis xyz="0 0 1" />
        <limit effort="12" lower="-0.0175" upper="3.7525" velocity="2.6100" />
    </joint>
    <link name="panda_link7">
        <visual>
            <geometry>
                <mesh filename="package://franka_description/meshes/visual/link7.dae" />
            </geometry>
        </visual>
        <collision>
            <origin rpy="0 0 0" xyz="0 0 0.01" />
            <geometry>
                <cylinder length="0.14" radius="0.04" />
            </geometry>
        </collision>
        <collision>
            <origin rpy="0 0 0" xyz="0 0 0.08" />
            <geometry>
                <sphere radius="0.04" />
            </geometry>
        </collision>
        <collision>
            <origin rpy="0 0 0" xyz="0 0 -0.06" />
            <geometry>
                <sphere radius="0.04" />
            </geometry>
        </collision>
        <!-- for simulation -->
        <inertial>
            <origin rpy="0 0 0" xyz="0 0 0" />
            <mass value="0.45" />
            <inertia ixx="0.3" ixy="0.0" ixz="0.0" iyy="0.3" iyz="0.0" izz="0.3" />
        </inertial>
        <!-- end for simulation -->
    </link>
    <joint name="panda_joint7" type="revolute">
        <safety_controller k_position="100.0" k_velocity="40.0" soft_lower_limit="-2.8973" soft_upper_limit="2.8973" />
        <origin rpy="1.5707963267948966 0 0" xyz="0.088 0 0" />
        <parent link="panda_link6" />
        <child link="panda_link7" />
        <axis xyz="0 0 1" />
        <limit effort="12" lower="-2.8973" upper="2.8973" velocity="2.6100" />
    </joint>
    <link name="panda_link8">
        <!-- for simulation -->
        <inertial>
            <origin rpy="0 0 0" xyz="0 0 0" />
            <mass value="0.45" />
            <inertia ixx="0.3" ixy="0.0" ixz="0.0" iyy="0.3" iyz="0.0" izz="0.3" />
        </inertial>
        <!-- end for simulation -->
    </link>
    <joint name="panda_joint8" type="fixed">
        <origin rpy="0 0 0" xyz="0 0 0.107" />
        <parent link="panda_link7" />
        <child link="panda_link8" />
    </joint>
    <gazebo>
        <plugin filename="libgazebo_grasp_fix.so" name="gazebo_grasp_fix">
            <arm>
                <arm_name>panda</arm_name>
                <palm_link>panda_link7</palm_link>
                <gripper_link>panda_leftfinger</gripper_link>
                <gripper_link>panda_rightfinger</gripper_link>
            </arm>
            <forces_angle_tolerance>100</forces_angle_tolerance>
            <update_rate>20</update_rate>
            <grip_count_threshold>4</grip_count_threshold>
            <max_grip_count>15</max_grip_count>
            <release_tolerance>0.005</release_tolerance>
            <disable_collisions_on_attach>true</disable_collisions_on_attach>
            <contact_topic>__default_topic__</contact_topic>
        </plugin>
        <plugin name="gazebo_ros_control" filename="libgazebo_ros_control.so">
            <robotNamespace>/</robotNamespace>
        </plugin>
    </gazebo>
    <!-- <gazebo>
      <plugin name="gazebo_grasp_fix" filename="libgazebo_grasp_fix.so">
        <arm>
           <arm_name>panda</arm_name>
           <palm_link> panda_link7  </palm_link>
           <gripper_link> panda_leftfinger </gripper_link>
           <gripper_link> panda_rightfinger </gripper_link>
        </arm>
       <forces_angle_tolerance>100</forces_angle_tolerance>
       <update_rate>4</update_rate>
       <grip_count_threshold>4</grip_count_threshold>
       <max_grip_count>8</max_grip_count>
       <release_tolerance>0.005</release_tolerance>
       <disable_collisions_on_attach>false</disable_collisions_on_attach>
       <contact_topic>__default_topic__</contact_topic>
      </plugin>  
    </gazebo> -->
    <joint name="panda_hand_joint" type="fixed">
        <parent link="panda_link8" />
        <child link="panda_hand" />
        <origin rpy="0 0 -0.7853981633974483" xyz="0 0 0" />
    </joint>
    <link name="panda_hand">
        <visual>
            <geometry>
                <mesh filename="package://franka_description/meshes/visual/hand.dae" />
            </geometry>
        </visual>
        <collision>
            <geometry>
                <mesh filename="package://franka_description/meshes/collision/hand.stl" />
            </geometry>
        </collision>
        <!-- for simulation -->
        <inertial>
            <origin rpy="0 0 0" xyz="0 0 0" />
            <mass value="0.68" />
            <inertia ixx="0.1" ixy="0.0" ixz="0.0" iyy="0.1" iyz="0.0" izz="0.1" />
        </inertial>
        <!-- end for simulation -->
    </link>
    <link name="panda_leftfinger">
        <visual>
            <geometry>
                <mesh filename="package://franka_description/meshes/visual/finger.dae" />
            </geometry>
        </visual>
        <collision>
            <geometry>
                <mesh filename="package://franka_description/meshes/collision/finger.stl" />
            </geometry>
        </collision>
        <!-- for simulation -->
        <inertial>
            <origin rpy="0 0 0" xyz="0 0 0" />
            <mass value="0.68" />
            <inertia ixx="0.1" ixy="0.0" ixz="0.0" iyy="0.1" iyz="0.0" izz="0.1" />
        </inertial>
        <!-- end for simulation -->
    </link>
    <link name="panda_rightfinger">
        <visual>
            <origin rpy="0 0 3.141592653589793" xyz="0 0 0" />
            <geometry>
                <mesh filename="package://franka_description/meshes/visual/finger.dae" />
            </geometry>
        </visual>
        <collision>
            <origin rpy="0 0 3.141592653589793" xyz="0 0 0" />
            <geometry>
                <mesh filename="package://franka_description/meshes/collision/finger.stl" />
            </geometry>
        </collision>
        <!-- for simulation -->
        <inertial>
            <origin rpy="0 0 0" xyz="0 0 0" />
            <mass value="0.68" />
            <inertia ixx="0.1" ixy="0.0" ixz="0.0" iyy="0.1" iyz="0.0" izz="0.1" />
        </inertial>
        <!-- end for simulation -->
    </link>
    <joint name="panda_finger_joint1" type="prismatic">
        <parent link="panda_hand" />
        <child link="panda_leftfinger" />
        <origin rpy="0 0 0" xyz="0 0 0.0584" />
        <axis xyz="0 1 0" />
        <limit effort="20" lower="0.0" upper="0.04" velocity="0.2" />
    </joint>
    <joint name="panda_finger_joint2" type="prismatic">
        <parent link="panda_hand" />
        <child link="panda_rightfinger" />
        <origin rpy="0 0 0" xyz="0 0 0.0584" />
        <axis xyz="0 -1 0" />
        <limit effort="20" lower="0.0" upper="0.04" velocity="0.2" />
        <mimic joint="panda_finger_joint1" />
    </joint>
    <!-- <gazebo reference="${ns}_leftfinger">
      <kp>10000000.0</kp>
      <kd>1.0</kd>
      <mu1>100000.0</mu1>
      <mu2>100000.0</mu2>
      <minDepth>0.001</minDepth>
    </gazebo>
    <gazebo reference="${ns}_rightfinger">
      <kp>10000000.0</kp>
      <kd>1.0</kd>
      <mu1>100000.0</mu1>
      <mu2>100000.0</mu2>
      <minDepth>0.001</minDepth>
    </gazebo> -->
    <gazebo reference="panda_link0">
        <material>Gazebo/White</material>
        <implicitSpringDamper>1</implicitSpringDamper>
        <mu1>10000.0</mu1>
        <mu2>10000.0</mu2>
    </gazebo>
    <gazebo reference="panda_link1">
        <material>Gazebo/White</material>
        <implicitSpringDamper>1</implicitSpringDamper>
        <mu1>10000.0</mu1>
        <mu2>10000.0</mu2>
    </gazebo>
    <gazebo reference="panda_link2">
        <material>Gazebo/White</material>
        <implicitSpringDamper>1</implicitSpringDamper>
        <mu1>10000.0</mu1>
        <mu2>10000.0</mu2>
    </gazebo>
    <gazebo reference="panda_link3">
        <material>Gazebo/White</material>
        <implicitSpringDamper>1</implicitSpringDamper>
        <mu1>10000.0</mu1>
        <mu2>10000.0</mu2>
    </gazebo>
    <gazebo reference="panda_link4">
        <material>Gazebo/White</material>
        <implicitSpringDamper>1</implicitSpringDamper>
        <mu1>10000.0</mu1>
        <mu2>10000.0</mu2>
    </gazebo>
    <gazebo reference="panda_link5">
        <material>Gazebo/White</material>
        <implicitSpringDamper>1</implicitSpringDamper>
        <mu1>10000.0</mu1>
        <mu2>10000.0</mu2>
    </gazebo>
    <gazebo reference="panda_link6">
        <material>Gazebo/White</material>
        <implicitSpringDamper>1</implicitSpringDamper>
        <mu1>10000.0</mu1>
        <mu2>10000.0</mu2>
    </gazebo>
    <gazebo reference="panda_link7">
        <material>Gazebo/White</material>
        <implicitSpringDamper>1</implicitSpringDamper>
        <mu1>10000.0</mu1>
        <mu2>10000.0</mu2>
    </gazebo>
    <gazebo reference="panda_link8">
        <material>Gazebo/White</material>
        <implicitSpringDamper>1</implicitSpringDamper>
        <mu1>10000.0</mu1>
        <mu2>10000.0</mu2>
    </gazebo>
    <gazebo reference="panda_hand">
        <material>Gazebo/Grey</material>
        <implicitSpringDamper>1</implicitSpringDamper>
        <kp>100000.0</kp>
        <kd>1.0</kd>
        <mu1>10000.0</mu1>
        <mu2>10000.0</mu2>
        <minDepth>0.001</minDepth>
    </gazebo>
    <gazebo reference="panda_rightfinger">
        <material>Gazebo/Grey</material>
        <implicitSpringDamper>1</implicitSpringDamper>
        <kp>100000.0</kp>
        <kd>1.0</kd>
        <mu1>10000.0</mu1>
        <mu2>10000.0</mu2>
        <minDepth>0.001</minDepth>
    </gazebo>
    <gazebo reference="panda_leftfinger">
        <material>Gazebo/Grey</material>
        <implicitSpringDamper>1</implicitSpringDamper>
        <kp>100000.0</kp>
        <kd>1.0</kd>
        <mu1>10000.0</mu1>
        <mu2>10000.0</mu2>
        <minDepth>0.001</minDepth>
    </gazebo>
    <transmission name="panda_tran_1">
        <type>transmission_interface/SimpleTransmission</type>
        <joint name="panda_joint1">
            <hardwareInterface>hardware_interface/PositionJointInterface</hardwareInterface>
        </joint>
        <actuator name="panda_motor_1">
            <hardwareInterface>hardware_interface/PositionJointInterface</hardwareInterface>
            <mechanicalReduction>1</mechanicalReduction>
        </actuator>
    </transmission>
    <transmission name="panda_tran_2">
        <type>transmission_interface/SimpleTransmission</type>
        <joint name="panda_joint2">
            <hardwareInterface>hardware_interface/PositionJointInterface</hardwareInterface>
        </joint>
        <actuator name="panda_motor_2">
            <hardwareInterface>hardware_interface/PositionJointInterface</hardwareInterface>
            <mechanicalReduction>1</mechanicalReduction>
        </actuator>
    </transmission>
    <transmission name="panda_tran_3">
        <type>transmission_interface/SimpleTransmission</type>
        <joint name="panda_joint3">
            <hardwareInterface>hardware_interface/PositionJointInterface</hardwareInterface>
        </joint>
        <actuator name="panda_motor_3">
            <hardwareInterface>hardware_interface/PositionJointInterface</hardwareInterface>
            <mechanicalReduction>1</mechanicalReduction>
        </actuator>
    </transmission>
    <transmission name="panda_tran_4">
        <type>transmission_interface/SimpleTransmission</type>
        <joint name="panda_joint4">
            <hardwareInterface>hardware_interface/PositionJointInterface</hardwareInterface>
        </joint>
        <actuator name="panda_motor_4">
            <hardwareInterface>hardware_interface/PositionJointInterface</hardwareInterface>
            <mechanicalReduction>1</mechanicalReduction>
        </actuator>
    </transmission>
    <transmission name="panda_tran_5">
        <type>transmission_interface/SimpleTransmission</type>
        <joint name="panda_joint5">
            <hardwareInterface>hardware_interface/PositionJointInterface</hardwareInterface>
        </joint>
        <actuator name="panda_motor_5">
            <hardwareInterface>hardware_interface/PositionJointInterface</hardwareInterface>
            <mechanicalReduction>1</mechanicalReduction>
        </actuator>
    </transmission>
    <transmission name="panda_tran_6">
        <type>transmission_interface/SimpleTransmission</type>
        <joint name="panda_joint6">
            <hardwareInterface>hardware_interface/PositionJointInterface</hardwareInterface>
        </joint>
        <actuator name="panda_motor_6">
            <hardwareInterface>hardware_interface/PositionJointInterface</hardwareInterface>
            <mechanicalReduction>1</mechanicalReduction>
        </actuator>
    </transmission>
    <transmission name="panda_tran_7">
        <type>transmission_interface/SimpleTransmission</type>
        <joint name="panda_joint7">
            <hardwareInterface>hardware_interface/PositionJointInterface</hardwareInterface>
        </joint>
        <actuator name="panda_motor_7">
            <hardwareInterface>hardware_interface/PositionJointInterface</hardwareInterface>
            <mechanicalReduction>1</mechanicalReduction>
        </actuator>
    </transmission>
    <transmission name="panda_leftfinger">
        <type>transmission_interface/SimpleTransmission</type>
        <joint name="panda_finger_joint1">
            <hardwareInterface>hardware_interface/EffortJointInterface</hardwareInterface>
        </joint>
        <actuator name="panda_finger_joint1">
            <hardwareInterface>hardware_interface/EffortJointInterface</hardwareInterface>
            <mechanicalReduction>1</mechanicalReduction>
        </actuator>
    </transmission>
    <transmission name="panda_rightfinger">
        <type>transmission_interface/SimpleTransmission</type>
        <joint name="panda_finger_joint2">
            <hardwareInterface>hardware_interface/EffortJointInterface</hardwareInterface>
        </joint>
        <actuator name="panda_finger_joint2">
            <hardwareInterface>hardware_interface/EffortJointInterface</hardwareInterface>
            <mechanicalReduction>1</mechanicalReduction>
        </actuator>
    </transmission>
    <gazebo>
        <plugin filename="libgazebo_ros_control.so" name="gazebo_ros_control" />
        <robotSimType>gazebo_ros_control/DefaultRobotHWSim</robotSimType>
    </gazebo>
    <!-- end for simulation -->
    <!-- joint/link data -->
    <!-- You can modify this to give the camera actual geometry -->
    <link name="camera_link" />
    <link name="panda_camera_optical_link" />
    <joint name="robot_camera_joint" type="fixed">
        <origin rpy="-1.57 -1.57 -0.785" xyz="0.05 -0.05 0" />
        <parent link="panda_link8" />
        <child link="camera_link" />
    </joint>
    <joint name="camera_optical_joint" type="fixed">
        <origin rpy="-1.57 0 -1.57" xyz="0 0 0" />
        <parent link="camera_link" />
        <child link="panda_camera_optical_link" />
    </joint>
    <!-- Sensor -->
    <gazebo reference="camera_link">
        <sensor name="panda_camera" type="depth">
            <always_on>1</always_on>
            <visualize>true</visualize>
            <update_rate>0</update_rate>
            <camera>
                <horizontal_fov>1.047198</horizontal_fov>
                <image>
                    <width>1024</width>
                    <height>1024</height>
                    <format>B8G8R8</format>
                    <!--Changed format since channels were inverted, to go back, change to R8G8B8-->
                </image>
                <clip>
                    <near>0.01</near>
                    <far>3</far>
                </clip>
            </camera>
            <plugin filename="libgazebo_ros_openni_kinect.so" name="camera_controller">
                <baseline>0.2</baseline>
                <alwaysOn>true</alwaysOn>
                <updateRate>0.0</updateRate>
                <cameraName>/panda_camera</cameraName>
                <imageTopicName>/panda_camera/rgb/image_raw</imageTopicName>
                <cameraInfoTopicName>/panda_camera/rgb/camera_info</cameraInfoTopicName>
                <depthImageTopicName>/panda_camera/depth/image_raw</depthImageTopicName>
                <depthImageInfoTopicName>/panda_camera/depth/camera_info</depthImageInfoTopicName>
                <pointCloudTopicName>/panda_camera/depth/points</pointCloudTopicName>
                <frameName>panda_camera_optical_link</frameName>
                <pointCloudCutoff>0.1</pointCloudCutoff>
                <pointCloudCutoffMax>3</pointCloudCutoffMax>
                <distortionK1>0</distortionK1>
                <distortionK2>0</distortionK2>
                <distortionK3>0</distortionK3>
                <distortionT1>0</distortionT1>
                <distortionT2>0</distortionT2>
                <CxPrime>0</CxPrime>
                <Cx>0</Cx>
                <Cy>0</Cy>
                <focalLength>0</focalLength>
                <hackBaseline>0</hackBaseline>
            </plugin>
        </sensor>
    </gazebo>
</robot>

